Workbook

Sheet DatiOriginali
A1: SeqId | B1: BubbleSortNComp | C1: BubbleSortTns | D1: InsertionSortNComp | E1: InsertionSortTns | F1: MergeSortNComp | G1: MergeSortTns | H1: QuickSortNComp | I1: QuickSortTns | J1: QuickSortRandomNComp | K1: QuickSortRandomTns
A2: seq_50_0 | B2: 1225 | C2: 11250800 | D2: 672 | E2: 187400 | F2: 226 | G2: 462800 | H2: 216 | I2: 147400 | J2: 258 | K2: 213700
A3: seq_50_1 | B3: 1225 | C3: 307000 | D3: 620 | E3: 138800 | F3: 452 | G3: 339500 | H3: 477 | I3: 85600 | J3: 485 | K3: 141400
A4: seq_50_2 | B4: 1225 | C4: 728600 | D4: 752 | E4: 273300 | F4: 677 | G4: 327300 | H4: 705 | I4: 82500 | J4: 829 | K4: 161100
A5: seq_50_3 | B5: 1225 | C5: 396200 | D5: 733 | E5: 186100 | F5: 899 | G5: 229800 | H5: 965 | I5: 85600 | J5: 1089 | K5: 108100
A6: seq_50_4 | B6: 1225 | C6: 457000 | D6: 718 | E6: 211900 | F6: 1118 | G6: 243900 | H6: 1235 | I6: 118300 | J6: 1317 | K6: 155900
A7: seq_50_5 | B7: 1225 | C7: 438300 | D7: 653 | E7: 186100 | F7: 1340 | G7: 121700 | H7: 1497 | I7: 141800 | J7: 1587 | K7: 143800
A8: seq_50_6 | B8: 1225 | C8: 408500 | D8: 562 | E8: 168900 | F8: 1560 | G8: 64400 | H8: 1784 | I8: 187900 | J8: 1843 | K8: 185900
A9: seq_50_7 | B9: 1225 | C9: 302100 | D9: 615 | E9: 120000 | F9: 1778 | G9: 99800 | H9: 2047 | I9: 81400 | J9: 2113 | K9: 92900
A10: seq_50_8 | B10: 1225 | C10: 290700 | D10: 629 | E10: 118300 | F10: 1997 | G10: 32400 | H10: 2301 | I10: 75800 | J10: 2338 | K10: 75800
A11: seq_50_9 | B11: 1225 | C11: 533700 | D11: 743 | E11: 213800 | F11: 2217 | G11: 62700 | H11: 2565 | I11: 98400 | J11: 2569 | K11: 113600
A12: seq_50_10 | B12: 1225 | C12: 436900 | D12: 687 | E12: 198700 | F12: 2437 | G12: 59400 | H12: 2813 | I12: 103200 | J12: 2828 | K12: 120600
A13: seq_50_11 | B13: 1225 | C13: 438200 | D13: 600 | E13: 173700 | F13: 2658 | G13: 76100 | H13: 3082 | I13: 105800 | J13: 3114 | K13: 110800
... A3001: seq_1500_99 | B3001: 1124250 | C3001: 10753100 | D3001: 567226 | E3001: 2314600 | F3001: 20017984 | G3001: 693800 | H3001: 25242795 | I3001: 225100 | J3001: 25184344 | K3001: 230400

Sheet Quartile1
A1: n | B1: BubbleSortTns | C1: InsertionSortTns | D1: MergeSortTns | E1: QuickSortTns | F1: QuickSortRandomTns
A2: 50 | B2: =QUARTILE(DatiOriginali!C2:C101,1) -> 50625 | C2: =QUARTILE(DatiOriginali!E2:E101,1) -> 122950 | D2: =QUARTILE(DatiOriginali!G2:G101,1) -> 36500 | E2: =QUARTILE(DatiOriginali!I2:I101,1) -> 13275 | F2: =QUARTILE(DatiOriginali!K2:K101,1) -> 14900
A3: 100 | B3: =QUARTILE(DatiOriginali!C102:C201,1) -> 42100 | C3: =QUARTILE(DatiOriginali!E102:E201,1) -> 17400 | D3: =QUARTILE(DatiOriginali!G102:G201,1) -> 45100 | E3: =QUARTILE(DatiOriginali!I102:I201,1) -> 12375 | F3: =QUARTILE(DatiOriginali!K102:K201,1) -> 14375
A4: 150 | B4: =QUARTILE(DatiOriginali!C202:C301,1) -> 74550 | C4: =QUARTILE(DatiOriginali!E202:E301,1) -> 23175 | D4: =QUARTILE(DatiOriginali!G202:G301,1) -> 56650 | E4: =QUARTILE(DatiOriginali!I202:I301,1) -> 15200 | F4: =QUARTILE(DatiOriginali!K202:K301,1) -> 18775
A5: 200 | B5: =QUARTILE(DatiOriginali!C302:C401,1) -> 132350 | C5: =QUARTILE(DatiOriginali!E302:E401,1) -> 38600 | D5: =QUARTILE(DatiOriginali!G302:G401,1) -> 71375 | E5: =QUARTILE(DatiOriginali!I302:I401,1) -> 20200 | F5: =QUARTILE(DatiOriginali!K302:K401,1) -> 25100
A6: 250 | B6: =QUARTILE(DatiOriginali!C402:C501,1) -> 211125 | C6: =QUARTILE(DatiOriginali!E402:E501,1) -> 60500 | D6: =QUARTILE(DatiOriginali!G402:G501,1) -> 91025 | E6: =QUARTILE(DatiOriginali!I402:I501,1) -> 26100 | F6: =QUARTILE(DatiOriginali!K402:K501,1) -> 30200
A7: 300 | B7: =QUARTILE(DatiOriginali!C502:C601,1) -> 284950 | C7: =QUARTILE(DatiOriginali!E502:E601,1) -> 81650 | D7: =QUARTILE(DatiOriginali!G502:G601,1) -> 109325 | E7: =QUARTILE(DatiOriginali!I502:I601,1) -> 31800 | F7: =QUARTILE(DatiOriginali!K502:K601,1) -> 36400
A8: 350 | B8: =QUARTILE(DatiOriginali!C602:C701,1) -> 401975 | C8: =QUARTILE(DatiOriginali!E602:E701,1) -> 110600 | D8: =QUARTILE(DatiOriginali!G602:G701,1) -> 123700 | E8: =QUARTILE(DatiOriginali!I602:I701,1) -> 37000 | F8: =QUARTILE(DatiOriginali!K602:K701,1) -> 42600
A9: 400 | B9: =QUARTILE(DatiOriginali!C702:C801,1) -> 528625 | C9: =QUARTILE(DatiOriginali!E702:E801,1) -> 141900 | D9: =QUARTILE(DatiOriginali!G702:G801,1) -> 136025 | E9: =QUARTILE(DatiOriginali!I702:I801,1) -> 44575 | F9: =QUARTILE(DatiOriginali!K702:K801,1) -> 50175
A10: 450 | B10: =QUARTILE(DatiOriginali!C802:C901,1) -> 676300 | C10: =QUARTILE(DatiOriginali!E802:E901,1) -> 180650 | D10: =QUARTILE(DatiOriginali!G802:G901,1) -> 156675 | E10: =QUARTILE(DatiOriginali!I802:I901,1) -> 49675 | F10: =QUARTILE(DatiOriginali!K802:K901,1) -> 56175
A11: 500 | B11: =QUARTILE(DatiOriginali!C902:C1001,1) -> 858125 | C11: =QUARTILE(DatiOriginali!E902:E1001,1) -> 225800 | D11: =QUARTILE(DatiOriginali!G902:G1001,1) -> 171500 | E11: =QUARTILE(DatiOriginali!I902:I1001,1) -> 56500 | F11: =QUARTILE(DatiOriginali!K902:K1001,1) -> 64400
A12: 550 | B12: =QUARTILE(DatiOriginali!C1002:C1101,1) -> 1060900 | C12: =QUARTILE(DatiOriginali!E1002:E1101,1) -> 265850 | D12: =QUARTILE(DatiOriginali!G1002:G1101,1) -> 191050 | E12: =QUARTILE(DatiOriginali!I1002:I1101,1) -> 62475 | F12: =QUARTILE(DatiOriginali!K1002:K1101,1) -> 71100
A13: 600 | B13: =QUARTILE(DatiOriginali!C1102:C1201,1) -> 1289475 | C13: =QUARTILE(DatiOriginali!E1102:E1201,1) -> 315600 | D13: =QUARTILE(DatiOriginali!G1102:G1201,1) -> 210725 | E13: =QUARTILE(DatiOriginali!I1102:I1201,1) -> 69275 | F13: =QUARTILE(DatiOriginali!K1102:K1201,1) -> 77800
A14: 650 | B14: =QUARTILE(DatiOriginali!C1202:C1301,1) -> 1547425 | C14: =QUARTILE(DatiOriginali!E1202:E1301,1) -> 367975 | D14: =QUARTILE(DatiOriginali!G1202:G1301,1) -> 227400 | E14: =QUARTILE(DatiOriginali!I1202:I1301,1) -> 76875 | F14: =QUARTILE(DatiOriginali!K1202:K1301,1) -> 85375
A15: 700 | B15: =QUARTILE(DatiOriginali!C1302:C1401,1) -> 1832950 | C15: =QUARTILE(DatiOriginali!E1302:E1401,1) -> 422250 | D15: =QUARTILE(DatiOriginali!G1302:G1401,1) -> 247700 | E15: =QUARTILE(DatiOriginali!I1302:I1401,1) -> 83100 | F15: =QUARTILE(DatiOriginali!K1302:K1401,1) -> 93000
A16: 750 | B16: =QUARTILE(DatiOriginali!C1402:C1501,1) -> 2149175 | C16: =QUARTILE(DatiOriginali!E1402:E1501,1) -> 484600 | D16: =QUARTILE(DatiOriginali!G1402:G1501,1) -> 269600 | E16: =QUARTILE(DatiOriginali!I1402:I1501,1) -> 90400 | F16: =QUARTILE(DatiOriginali!K1402:K1501,1) -> 100375
A17: 800 | B17: =QUARTILE(DatiOriginali!C1502:C1601,1) -> 2491175 | C17: =QUARTILE(DatiOriginali!E1502:E1601,1) -> 553375 | D17: =QUARTILE(DatiOriginali!G1502:G1601,1) -> 290225 | E17: =QUARTILE(DatiOriginali!I1502:I1601,1) -> 97000 | F17: =QUARTILE(DatiOriginali!K1502:K1601,1) -> 108475
A18: 850 | B18: =QUARTILE(DatiOriginali!C1602:C1701,1) -> 2863150 | C18: =QUARTILE(DatiOriginali!E1602:E1701,1) -> 626275 | D18: =QUARTILE(DatiOriginali!G1602:G1701,1) -> 309900 | E18: =QUARTILE(DatiOriginali!I1602:I1701,1) -> 104350 | F18: =QUARTILE(DatiOriginali!K1602:K1701,1) -> 116000
A19: 900 | B19: =QUARTILE(DatiOriginali!C1702:C1801,1) -> 3252425 | C19: =QUARTILE(DatiOriginali!E1702:E1801,1) -> 698750 | D19: =QUARTILE(DatiOriginali!G1702:G1801,1) -> 326675 | E19: =QUARTILE(DatiOriginali!I1702:I1801,1) -> 111275 | F19: =QUARTILE(DatiOriginali!K1702:K1801,1) -> 123175
A20: 950 | B20: =QUARTILE(DatiOriginali!C1802:C1901,1) -> 3664250 | C20: =QUARTILE(DatiOriginali!E1802:E1901,1) -> 780150 | D20: =QUARTILE(DatiOriginali!G1802:G1901,1) -> 349650 | E20: =QUARTILE(DatiOriginali!I1802:I1901,1) -> 118500 | F20: =QUARTILE(DatiOriginali!K1802:K1901,1) -> 131000
A21: 1000 | B21: =QUARTILE(DatiOriginali!C1902:C2001,1) -> 4118650 | C21: =QUARTILE(DatiOriginali!E1902:E2001,1) -> 865375 | D21: =QUARTILE(DatiOriginali!G1902:G2001,1) -> 370400 | E21: =QUARTILE(DatiOriginali!I1902:I2001,1) -> 126600 | F21: =QUARTILE(DatiOriginali!K1902:K2001,1) -> 139500
A22: 1050 | B22: =QUARTILE(DatiOriginali!C2002:C2101,1) -> 4613275 | C22: =QUARTILE(DatiOriginali!E2002:E2101,1) -> 952650 | D22: =QUARTILE(DatiOriginali!G2002:G2101,1) -> 391600 | E22: =QUARTILE(DatiOriginali!I2002:I2101,1) -> 133500 | F22: =QUARTILE(DatiOriginali!K2002:K2101,1) -> 147500
A23: 1100 | B23: =QUARTILE(DatiOriginali!C2102:C2201,1) -> 5143300 | C23: =QUARTILE(DatiOriginali!E2102:E2201,1) -> 1047725 | D23: =QUARTILE(DatiOriginali!G2102:G2201,1) -> 415175 | E23: =QUARTILE(DatiOriginali!I2102:I2201,1) -> 140700 | F23: =QUARTILE(DatiOriginali!K2102:K2201,1) -> 155900
A24: 1150 | B24: =QUARTILE(DatiOriginali!C2202:C2301,1) -> 5660850 | C24: =QUARTILE(DatiOriginali!E2202:E2301,1) -> 1143675 | D24: =QUARTILE(DatiOriginali!G2202:G2301,1) -> 434275 | E24: =QUARTILE(DatiOriginali!I2202:I2301,1) -> 147975 | F24: =QUARTILE(DatiOriginali!K2202:K2301,1) -> 163475
A25: 1200 | B25: =QUARTILE(DatiOriginali!C2302:C2401,1) -> 6220350 | C25: =QUARTILE(DatiOriginali!E2302:E2401,1) -> 1242700 | D25: =QUARTILE(DatiOriginali!G2302:G2401,1) -> 456450 | E25: =QUARTILE(DatiOriginali!I2302:I2401,1) -> 155400 | F25: =QUARTILE(DatiOriginali!K2302:K2401,1) -> 171375
A26: 1250 | B26: =QUARTILE(DatiOriginali!C2402:C2501,1) -> 6828875 | C26: =QUARTILE(DatiOriginali!E2402:E2501,1) -> 1347250 | D26: =QUARTILE(DatiOriginali!G2402:G2501,1) -> 474475 | E26: =QUARTILE(DatiOriginali!I2402:I2501,1) -> 164650 | F26: =QUARTILE(DatiOriginali!K2402:K2501,1) -> 180650
A27: 1300 | B27: =QUARTILE(DatiOriginali!C2502:C2601,1) -> 7492875 | C27: =QUARTILE(DatiOriginali!E2502:E2601,1) -> 1461750 | D27: =QUARTILE(DatiOriginali!G2502:G2601,1) -> 493850 | E27: =QUARTILE(DatiOriginali!I2502:I2601,1) -> 173400 | F27: =QUARTILE(DatiOriginali!K2502:K2601,1) -> 188175
A28: 1350 | B28: =QUARTILE(DatiOriginali!C2602:C2701,1) -> 8154875 | C28: =QUARTILE(DatiOriginali!E2602:E2701,1) -> 1576650 | D28: =QUARTILE(DatiOriginali!G2602:G2701,1) -> 517875 | E28: =QUARTILE(DatiOriginali!I2602:I2701,1) -> 177975 | F28: =QUARTILE(DatiOriginali!K2602:K2701,1) -> 196200
A29: 1400 | B29: =QUARTILE(DatiOriginali!C2702:C2801,1) -> 8828550 | C29: =QUARTILE(DatiOriginali!E2702:E2801,1) -> 1690100 | D29: =QUARTILE(DatiOriginali!G2702:G2801,1) -> 541750 | E29: =QUARTILE(DatiOriginali!I2702:I2801,1) -> 185900 | F29: =QUARTILE(DatiOriginali!K2702:K2801,1) -> 205475
A30: 1450 | B30: =QUARTILE(DatiOriginali!C2802:C2901,1) -> 9570425 | C30: =QUARTILE(DatiOriginali!E2802:E2901,1) -> 1806050 | D30: =QUARTILE(DatiOriginali!G2802:G2901,1) -> 563075 | E30: =QUARTILE(DatiOriginali!I2802:I2901,1) -> 193950 | F30: =QUARTILE(DatiOriginali!K2802:K2901,1) -> 213125
A31: 1500 | B31: =QUARTILE(DatiOriginali!C2902:C3001,1) -> 10336100 | C31: =QUARTILE(DatiOriginali!E2902:E3001,1) -> 1944375 | D31: =QUARTILE(DatiOriginali!G2902:G3001,1) -> 579775 | E31: =QUARTILE(DatiOriginali!I2902:I3001,1) -> 200875 | F31: =QUARTILE(DatiOriginali!K2902:K3001,1) -> 221900
A1048576: =SUM(A2:A1048575) -> 23250

Sheet Quartile3
A1: n | B1: BubbleSortTns | C1: InsertionSortTns | D1: MergeSortTns | E1: QuickSortTns | F1: QuickSortRandomTns
A2: 50 | B2: =QUARTILE(DatiOriginali!C2:C101,3) -> 321500 | C2: =QUARTILE(DatiOriginali!E2:E101,3) -> 176850 | D2: =QUARTILE(DatiOriginali!G2:G101,3) -> 144000 | E2: =QUARTILE(DatiOriginali!I2:I101,3) -> 75950 | F2: =QUARTILE(DatiOriginali!K2:K101,3) -> 29850
A3: 100 | B3: =QUARTILE(DatiOriginali!C102:C201,3) -> 50275 | C3: =QUARTILE(DatiOriginali!E102:E201,3) -> 135125 | D3: =QUARTILE(DatiOriginali!G102:G201,3) -> 63300 | E3: =QUARTILE(DatiOriginali!I102:I201,3) -> 14000 | F3: =QUARTILE(DatiOriginali!K102:K201,3) -> 19000
A4: 150 | B4: =QUARTILE(DatiOriginali!C202:C301,3) -> 90725 | C4: =QUARTILE(DatiOriginali!E202:E301,3) -> 28925 | D4: =QUARTILE(DatiOriginali!G202:G301,3) -> 74650 | E4: =QUARTILE(DatiOriginali!I202:I301,3) -> 19000 | F4: =QUARTILE(DatiOriginali!K202:K301,3) -> 23325
A5: 200 | B5: =QUARTILE(DatiOriginali!C302:C401,3) -> 166700 | C5: =QUARTILE(DatiOriginali!E302:E401,3) -> 57625 | D5: =QUARTILE(DatiOriginali!G302:G401,3) -> 94075 | E5: =QUARTILE(DatiOriginali!I302:I401,3) -> 25725 | F5: =QUARTILE(DatiOriginali!K302:K401,3) -> 32325
A6: 250 | B6: =QUARTILE(DatiOriginali!C402:C501,3) -> 265775 | C6: =QUARTILE(DatiOriginali!E402:E501,3) -> 86725 | D6: =QUARTILE(DatiOriginali!G402:G501,3) -> 124150 | E6: =QUARTILE(DatiOriginali!I402:I501,3) -> 32600 | F6: =QUARTILE(DatiOriginali!K402:K501,3) -> 37200
A7: 300 | B7: =QUARTILE(DatiOriginali!C502:C601,3) -> 325600 | C7: =QUARTILE(DatiOriginali!E502:E601,3) -> 92475 | D7: =QUARTILE(DatiOriginali!G502:G601,3) -> 122025 | E7: =QUARTILE(DatiOriginali!I502:I601,3) -> 33425 | F7: =QUARTILE(DatiOriginali!K502:K601,3) -> 38875
A8: 350 | B8: =QUARTILE(DatiOriginali!C602:C701,3) -> 462000 | C8: =QUARTILE(DatiOriginali!E602:E701,3) -> 131750 | D8: =QUARTILE(DatiOriginali!G602:G701,3) -> 153325 | E8: =QUARTILE(DatiOriginali!I602:I701,3) -> 44400 | F8: =QUARTILE(DatiOriginali!K602:K701,3) -> 50900
A9: 400 | B9: =QUARTILE(DatiOriginali!C702:C801,3) -> 615425 | C9: =QUARTILE(DatiOriginali!E702:E801,3) -> 158675 | D9: =QUARTILE(DatiOriginali!G702:G801,3) -> 164400 | E9: =QUARTILE(DatiOriginali!I702:I801,3) -> 52125 | F9: =QUARTILE(DatiOriginali!K702:K801,3) -> 57900
A10: 450 | B10: =QUARTILE(DatiOriginali!C802:C901,3) -> 789200 | C10: =QUARTILE(DatiOriginali!E802:E901,3) -> 217350 | D10: =QUARTILE(DatiOriginali!G802:G901,3) -> 182850 | E10: =QUARTILE(DatiOriginali!I802:I901,3) -> 56000 | F10: =QUARTILE(DatiOriginali!K802:K901,3) -> 59550
A11: 500 | B11: =QUARTILE(DatiOriginali!C902:C1001,3) -> 1038725 | C11: =QUARTILE(DatiOriginali!E902:E1001,3) -> 268600 | D11: =QUARTILE(DatiOriginali!G902:G1001,3) -> 203750 | E11: =QUARTILE(DatiOriginali!I902:I1001,3) -> 66075 | F11: =QUARTILE(DatiOriginali!K902:K1001,3) -> 72250
A12: 550 | B12: =QUARTILE(DatiOriginali!C1002:C1101,3) -> 1253525 | C12: =QUARTILE(DatiOriginali!E1002:E1101,3) -> 317100 | D12: =QUARTILE(DatiOriginali!G1002:G1101,3) -> 204200 | E12: =QUARTILE(DatiOriginali!I1002:I1101,3) -> 65925 | F12: =QUARTILE(DatiOriginali!K1002:K1101,3) -> 75000
A13: 600 | B13: =QUARTILE(DatiOriginali!C1102:C1201,3) -> 1519350 | C13: =QUARTILE(DatiOriginali!E1102:E1201,3) -> 338225 | D13: =QUARTILE(DatiOriginali!G1102:G1201,3) -> 218300 | E13: =QUARTILE(DatiOriginali!I1102:I1201,3) -> 71775 | F13: =QUARTILE(DatiOriginali!K1102:K1201,3) -> 81100
A14: 650 | B14: =QUARTILE(DatiOriginali!C1202:C1301,3) -> 1767125 | C14: =QUARTILE(DatiOriginali!E1202:E1301,3) -> 395875 | D14: =QUARTILE(DatiOriginali!G1202:G1301,3) -> 232325 | E14: =QUARTILE(DatiOriginali!I1202:I1301,3) -> 79200 | F14: =QUARTILE(DatiOriginali!K1202:K1301,3) -> 88200
A15: 700 | B15: =QUARTILE(DatiOriginali!C1302:C1401,3) -> 2066300 | C15: =QUARTILE(DatiOriginali!E1302:E1401,3) -> 453300 | D15: =QUARTILE(DatiOriginali!G1302:G1401,3) -> 253025 | E15: =QUARTILE(DatiOriginali!I1302:I1401,3) -> 85625 | F15: =QUARTILE(DatiOriginali!K1302:K1401,3) -> 96775
A16: 750 | B16: =QUARTILE(DatiOriginali!C1402:C1501,3) -> 2404725 | C16: =QUARTILE(DatiOriginali!E1402:E1501,3) -> 509475 | D16: =QUARTILE(DatiOriginali!G1402:G1501,3) -> 274925 | E16: =QUARTILE(DatiOriginali!I1402:I1501,3) -> 94625 | F16: =QUARTILE(DatiOriginali!K1402:K1501,3) -> 104150
A17: 800 | B17: =QUARTILE(DatiOriginali!C1502:C1601,3) -> 2643050 | C17: =QUARTILE(DatiOriginali!E1502:E1601,3) -> 580550 | D17: =QUARTILE(DatiOriginali!G1502:G1601,3) -> 296150 | E17: =QUARTILE(DatiOriginali!I1502:I1601,3) -> 100950 | F17: =QUARTILE(DatiOriginali!K1502:K1601,3) -> 112125
A18: 850 | B18: =QUARTILE(DatiOriginali!C1602:C1701,3) -> 3097325 | C18: =QUARTILE(DatiOriginali!E1602:E1701,3) -> 656875 | D18: =QUARTILE(DatiOriginali!G1602:G1701,3) -> 316425 | E18: =QUARTILE(DatiOriginali!I1602:I1701,3) -> 106900 | F18: =QUARTILE(DatiOriginali!K1602:K1701,3) -> 119375
A19: 900 | B19: =QUARTILE(DatiOriginali!C1702:C1801,3) -> 3431050 | C19: =QUARTILE(DatiOriginali!E1702:E1801,3) -> 725350 | D19: =QUARTILE(DatiOriginali!G1702:G1801,3) -> 332750 | E19: =QUARTILE(DatiOriginali!I1702:I1801,3) -> 114950 | F19: =QUARTILE(DatiOriginali!K1702:K1801,3) -> 127900
A20: 950 | B20: =QUARTILE(DatiOriginali!C1802:C1901,3) -> 3965225 | C20: =QUARTILE(DatiOriginali!E1802:E1901,3) -> 810400 | D20: =QUARTILE(DatiOriginali!G1802:G1901,3) -> 355625 | E20: =QUARTILE(DatiOriginali!I1802:I1901,3) -> 122725 | F20: =QUARTILE(DatiOriginali!K1802:K1901,3) -> 136400
A21: 1000 | B21: =QUARTILE(DatiOriginali!C1902:C2001,3) -> 4375275 | C21: =QUARTILE(DatiOriginali!E1902:E2001,3) -> 915600 | D21: =QUARTILE(DatiOriginali!G1902:G2001,3) -> 379775 | E21: =QUARTILE(DatiOriginali!I1902:I2001,3) -> 131600 | F21: =QUARTILE(DatiOriginali!K1902:K2001,3) -> 144800
A22: 1050 | B22: =QUARTILE(DatiOriginali!C2002:C2101,3) -> 4928475 | C22: =QUARTILE(DatiOriginali!E2002:E2101,3) -> 1005625 | D22: =QUARTILE(DatiOriginali!G2002:G2101,3) -> 402750 | E22: =QUARTILE(DatiOriginali!I2002:I2101,3) -> 138425 | F22: =QUARTILE(DatiOriginali!K2002:K2101,3) -> 151700
A23: 1100 | B23: =QUARTILE(DatiOriginali!C2102:C2201,3) -> 5416100 | C23: =QUARTILE(DatiOriginali!E2102:E2201,3) -> 1092250 | D23: =QUARTILE(DatiOriginali!G2102:G2201,3) -> 424400 | E23: =QUARTILE(DatiOriginali!I2102:I2201,3) -> 145700 | F23: =QUARTILE(DatiOriginali!K2102:K2201,3) -> 160775
A24: 1150 | B24: =QUARTILE(DatiOriginali!C2202:C2301,3) -> 5980025 | C24: =QUARTILE(DatiOriginali!E2202:E2301,3) -> 1193975 | D24: =QUARTILE(DatiOriginali!G2202:G2301,3) -> 442100 | E24: =QUARTILE(DatiOriginali!I2202:I2301,3) -> 152150 | F24: =QUARTILE(DatiOriginali!K2202:K2301,3) -> 170425
A25: 1200 | B25: =QUARTILE(DatiOriginali!C2302:C2401,3) -> 6506775 | C25: =QUARTILE(DatiOriginali!E2302:E2401,3) -> 1301225 | D25: =QUARTILE(DatiOriginali!G2302:G2401,3) -> 462800 | E25: =QUARTILE(DatiOriginali!I2302:I2401,3) -> 160250 | F25: =QUARTILE(DatiOriginali!K2302:K2401,3) -> 176400
A26: 1250 | B26: =QUARTILE(DatiOriginali!C2402:C2501,3) -> 7205975 | C26: =QUARTILE(DatiOriginali!E2402:E2501,3) -> 1440250 | D26: =QUARTILE(DatiOriginali!G2402:G2501,3) -> 486325 | E26: =QUARTILE(DatiOriginali!I2402:I2501,3) -> 170425 | F26: =QUARTILE(DatiOriginali!K2402:K2501,3) -> 186050
A27: 1300 | B27: =QUARTILE(DatiOriginali!C2502:C2601,3) -> 7844075 | C27: =QUARTILE(DatiOriginali!E2502:E2601,3) -> 1530500 | D27: =QUARTILE(DatiOriginali!G2502:G2601,3) -> 505025 | E27: =QUARTILE(DatiOriginali!I2502:I2601,3) -> 179225 | F27: =QUARTILE(DatiOriginali!K2502:K2601,3) -> 193725
A28: 1350 | B28: =QUARTILE(DatiOriginali!C2602:C2701,3) -> 8459475 | C28: =QUARTILE(DatiOriginali!E2602:E2701,3) -> 1634075 | D28: =QUARTILE(DatiOriginali!G2602:G2701,3) -> 528375 | E28: =QUARTILE(DatiOriginali!I2602:I2701,3) -> 183700 | F28: =QUARTILE(DatiOriginali!K2602:K2701,3) -> 201975
A29: 1400 | B29: =QUARTILE(DatiOriginali!C2702:C2801,3) -> 9161750 | C29: =QUARTILE(DatiOriginali!E2702:E2801,3) -> 1806575 | D29: =QUARTILE(DatiOriginali!G2702:G2801,3) -> 555600 | E29: =QUARTILE(DatiOriginali!I2702:I2801,3) -> 191100 | F29: =QUARTILE(DatiOriginali!K2702:K2801,3) -> 212600
A30: 1450 | B30: =QUARTILE(DatiOriginali!C2802:C2901,3) -> 10092700 | C30: =QUARTILE(DatiOriginali!E2802:E2901,3) -> 1908725 | D30: =QUARTILE(DatiOriginali!G2802:G2901,3) -> 574950 | E30: =QUARTILE(DatiOriginali!I2802:I2901,3) -> 200550 | F30: =QUARTILE(DatiOriginali!K2802:K2901,3) -> 220675
A31: 1500 | B31: =QUARTILE(DatiOriginali!C2902:C3001,3) -> 10776150 | C31: =QUARTILE(DatiOriginali!E2902:E3001,3) -> 2068225 | D31: =QUARTILE(DatiOriginali!G2902:G3001,3) -> 591750 | E31: =QUARTILE(DatiOriginali!I2902:I3001,3) -> 208000 | F31: =QUARTILE(DatiOriginali!K2902:K3001,3) -> 228025

Sheet SogliaPicchi
A1: n | B1: BubbleSortTns | C1: InsertionSortTns | D1: MergeSortTns | E1: QuickSortTns | F1: QuickSortRandomTns | G1: COSTANTE
A2: 50 | B2: =Quartile3!B2 + G2 * (Quartile3!B2 - Quartile1!B2) -> 1134125 | C2: =Quartile3!C2 + G2 * (Quartile3!C2 - Quartile1!C2) -> 338550 | D2: =Quartile3!D2 + G2 * (Quartile3!D2 - Quartile1!D2) -> 466500 | E2: =Quartile3!E2 + G2 * (Quartile3!E2 - Quartile1!E2) -> 263975 | F2: =Quartile3!F2 + G2 * (Quartile3!F2 - Quartile1!F2) -> 74700 | G2: 3
A3: 100 | B3: =Quartile3!B3 + G3 * (Quartile3!B3 - Quartile1!B3) -> 74800 | C3: =Quartile3!C3 + G3 * (Quartile3!C3 - Quartile1!C3) -> 488300 | D3: =Quartile3!D3 + G3 * (Quartile3!D3 - Quartile1!D3) -> 117900 | E3: =Quartile3!E3 + G3 * (Quartile3!E3 - Quartile1!E3) -> 18875 | F3: =Quartile3!F3 + G3 * (Quartile3!F3 - Quartile1!F3) -> 32875 | G3: 3
A4: 150 | B4: =Quartile3!B4 + G4 * (Quartile3!B4 - Quartile1!B4) -> 139250 | C4: =Quartile3!C4 + G4 * (Quartile3!C4 - Quartile1!C4) -> 46175 | D4: =Quartile3!D4 + G4 * (Quartile3!D4 - Quartile1!D4) -> 128650 | E4: =Quartile3!E4 + G4 * (Quartile3!E4 - Quartile1!E4) -> 30400 | F4: =Quartile3!F4 + G4 * (Quartile3!F4 - Quartile1!F4) -> 36975 | G4: 3
A5: 200 | B5: =Quartile3!B5 + G5 * (Quartile3!B5 - Quartile1!B5) -> 269750 | C5: =Quartile3!C5 + G5 * (Quartile3!C5 - Quartile1!C5) -> 114700 | D5: =Quartile3!D5 + G5 * (Quartile3!D5 - Quartile1!D5) -> 162175 | E5: =Quartile3!E5 + G5 * (Quartile3!E5 - Quartile1!E5) -> 42300 | F5: =Quartile3!F5 + G5 * (Quartile3!F5 - Quartile1!F5) -> 54000 | G5: 3
A6: 250 | B6: =Quartile3!B6 + G6 * (Quartile3!B6 - Quartile1!B6) -> 429725 | C6: =Quartile3!C6 + G6 * (Quartile3!C6 - Quartile1!C6) -> 165400 | D6: =Quartile3!D6 + G6 * (Quartile3!D6 - Quartile1!D6) -> 223525 | E6: =Quartile3!E6 + G6 * (Quartile3!E6 - Quartile1!E6) -> 52100 | F6: =Quartile3!F6 + G6 * (Quartile3!F6 - Quartile1!F6) -> 58200 | G6: 3
A7: 300 | B7: =Quartile3!B7 + G7 * (Quartile3!B7 - Quartile1!B7) -> 447550 | C7: =Quartile3!C7 + G7 * (Quartile3!C7 - Quartile1!C7) -> 124950 | D7: =Quartile3!D7 + G7 * (Quartile3!D7 - Quartile1!D7) -> 160125 | E7: =Quartile3!E7 + G7 * (Quartile3!E7 - Quartile1!E7) -> 38300 | F7: =Quartile3!F7 + G7 * (Quartile3!F7 - Quartile1!F7) -> 46300 | G7: 3
A8: 350 | B8: =Quartile3!B8 + G8 * (Quartile3!B8 - Quartile1!B8) -> 642075 | C8: =Quartile3!C8 + G8 * (Quartile3!C8 - Quartile1!C8) -> 195200 | D8: =Quartile3!D8 + G8 * (Quartile3!D8 - Quartile1!D8) -> 242200 | E8: =Quartile3!E8 + G8 * (Quartile3!E8 - Quartile1!E8) -> 66600 | F8: =Quartile3!F8 + G8 * (Quartile3!F8 - Quartile1!F8) -> 75800 | G8: 3
A9: 400 | B9: =Quartile3!B9 + G9 * (Quartile3!B9 - Quartile1!B9) -> 875825 | C9: =Quartile3!C9 + G9 * (Quartile3!C9 - Quartile1!C9) -> 209000 | D9: =Quartile3!D9 + G9 * (Quartile3!D9 - Quartile1!D9) -> 249525 | E9: =Quartile3!E9 + G9 * (Quartile3!E9 - Quartile1!E9) -> 74775 | F9: =Quartile3!F9 + G9 * (Quartile3!F9 - Quartile1!F9) -> 81075 | G9: 3
A10: 450 | B10: =Quartile3!B10 + G10 * (Quartile3!B10 - Quartile1!B10) -> 1127900 | C10: =Quartile3!C10 + G10 * (Quartile3!C10 - Quartile1!C10) -> 327450 | D10: =Quartile3!D10 + G10 * (Quartile3!D10 - Quartile1!D10) -> 261375 | E10: =Quartile3!E10 + G10 * (Quartile3!E10 - Quartile1!E10) -> 74975 | F10: =Quartile3!F10 + G10 * (Quartile3!F10 - Quartile1!F10) -> 69675 | G10: 3
A11: 500 | B11: =Quartile3!B11 + G11 * (Quartile3!B11 - Quartile1!B11) -> 1580525 | C11: =Quartile3!C11 + G11 * (Quartile3!C11 - Quartile1!C11) -> 397000 | D11: =Quartile3!D11 + G11 * (Quartile3!D11 - Quartile1!D11) -> 300500 | E11: =Quartile3!E11 + G11 * (Quartile3!E11 - Quartile1!E11) -> 94800 | F11: =Quartile3!F11 + G11 * (Quartile3!F11 - Quartile1!F11) -> 95800 | G11: 3
A12: 550 | B12: =Quartile3!B12 + G12 * (Quartile3!B12 - Quartile1!B12) -> 1831400 | C12: =Quartile3!C12 + G12 * (Quartile3!C12 - Quartile1!C12) -> 470850 | D12: =Quartile3!D12 + G12 * (Quartile3!D12 - Quartile1!D12) -> 243650 | E12: =Quartile3!E12 + G12 * (Quartile3!E12 - Quartile1!E12) -> 76275 | F12: =Quartile3!F12 + G12 * (Quartile3!F12 - Quartile1!F12) -> 86700 | G12: 3
A13: 600 | B13: =Quartile3!B13 + G13 * (Quartile3!B13 - Quartile1!B13) -> 2208975 | C13: =Quartile3!C13 + G13 * (Quartile3!C13 - Quartile1!C13) -> 406100 | D13: =Quartile3!D13 + G13 * (Quartile3!D13 - Quartile1!D13) -> 241025 | E13: =Quartile3!E13 + G13 * (Quartile3!E13 - Quartile1!E13) -> 79275 | F13: =Quartile3!F13 + G13 * (Quartile3!F13 - Quartile1!F13) -> 91000 | G13: 3
... A31: 1500 | B31: =Quartile3!B31 + G31 * (Quartile3!B31 - Quartile1!B31) -> 12096300 | C31: =Quartile3!C31 + G31 * (Quartile3!C31 - Quartile1!C31) -> 2439775 | D31: =Quartile3!D31 + G31 * (Quartile3!D31 - Quartile1!D31) -> 627675 | E31: =Quartile3!E31 + G31 * (Quartile3!E31 - Quartile1!E31) -> 229375 | F31: =Quartile3!F31 + G31 * (Quartile3!F31 - Quartile1!F31) -> 246400 | G31: 3

Sheet DatiRipuliti
A1: SeqId | B1: BubbleSortNComp | C1: BubbleSortTns | D1: InsertionSortNComp | E1: InsertionSortTns | F1: MergeSortNComp | G1: MergeSortTns | H1: QuickSortNComp | I1: QuickSortTns | J1: QuickSortRandomNComp | K1: QuickSortRandomTns
A2: seq_50_0 | B2: 1225 | C2: =IF(DatiOriginali!C2 >= SogliaPicchi!$B$2,"",DatiOriginali!C2) | D2: 672 | E2: =IF(DatiOriginali!E2 >= SogliaPicchi!$B$2,"",DatiOriginali!E2) -> 187400 | F2: 226 | G2: =IF(DatiOriginali!G2 >= SogliaPicchi!$B$2,"",DatiOriginali!G2) -> 462800 | H2: 216 | I2: =IF(DatiOriginali!I2 >= SogliaPicchi!$B$2,"",DatiOriginali!I2) -> 147400 | J2: 258 | K2: =IF(DatiOriginali!K2 >= SogliaPicchi!$B$2,"",DatiOriginali!K2) -> 213700
A3: seq_50_1 | B3: 1225 | C3: =IF(DatiOriginali!C3 >= SogliaPicchi!$B$2,"",DatiOriginali!C3) -> 307000 | D3: 620 | E3: =IF(DatiOriginali!E3 >= SogliaPicchi!$B$2,"",DatiOriginali!E3) -> 138800 | F3: 452 | G3: =IF(DatiOriginali!G3 >= SogliaPicchi!$B$2,"",DatiOriginali!G3) -> 339500 | H3: 477 | I3: =IF(DatiOriginali!I3 >= SogliaPicchi!$B$2,"",DatiOriginali!I3) -> 85600 | J3: 485 | K3: =IF(DatiOriginali!K3 >= SogliaPicchi!$B$2,"",DatiOriginali!K3) -> 141400
A4: seq_50_2 | B4: 1225 | C4: =IF(DatiOriginali!C4 >= SogliaPicchi!$B$2,"",DatiOriginali!C4) -> 728600 | D4: 752 | E4: =IF(DatiOriginali!E4 >= SogliaPicchi!$B$2,"",DatiOriginali!E4) -> 273300 | F4: 677 | G4: =IF(DatiOriginali!G4 >= SogliaPicchi!$B$2,"",DatiOriginali!G4) -> 327300 | H4: 705 | I4: =IF(DatiOriginali!I4 >= SogliaPicchi!$B$2,"",DatiOriginali!I4) -> 82500 | J4: 829 | K4: =IF(DatiOriginali!K4 >= SogliaPicchi!$B$2,"",DatiOriginali!K4) -> 161100
A5: seq_50_3 | B5: 1225 | C5: =IF(DatiOriginali!C5 >= SogliaPicchi!$B$2,"",DatiOriginali!C5) -> 396200 | D5: 733 | E5: =IF(DatiOriginali!E5 >= SogliaPicchi!$B$2,"",DatiOriginali!E5) -> 186100 | F5: 899 | G5: =IF(DatiOriginali!G5 >= SogliaPicchi!$B$2,"",DatiOriginali!G5) -> 229800 | H5: 965 | I5: =IF(DatiOriginali!I5 >= SogliaPicchi!$B$2,"",DatiOriginali!I5) -> 85600 | J5: 1089 | K5: =IF(DatiOriginali!K5 >= SogliaPicchi!$B$2,"",DatiOriginali!K5) -> 108100
A6: seq_50_4 | B6: 1225 | C6: =IF(DatiOriginali!C6 >= SogliaPicchi!$B$2,"",DatiOriginali!C6) -> 457000 | D6: 718 | E6: =IF(DatiOriginali!E6 >= SogliaPicchi!$B$2,"",DatiOriginali!E6) -> 211900 | F6: 1118 | G6: =IF(DatiOriginali!G6 >= SogliaPicchi!$B$2,"",DatiOriginali!G6) -> 243900 | H6: 1235 | I6: =IF(DatiOriginali!I6 >= SogliaPicchi!$B$2,"",DatiOriginali!I6) -> 118300 | J6: 1317 | K6: =IF(DatiOriginali!K6 >= SogliaPicchi!$B$2,"",DatiOriginali!K6) -> 155900
A7: seq_50_5 | B7: 1225 | C7: =IF(DatiOriginali!C7 >= SogliaPicchi!$B$2,"",DatiOriginali!C7) -> 438300 | D7: 653 | E7: =IF(DatiOriginali!E7 >= SogliaPicchi!$B$2,"",DatiOriginali!E7) -> 186100 | F7: 1340 | G7: =IF(DatiOriginali!G7 >= SogliaPicchi!$B$2,"",DatiOriginali!G7) -> 121700 | H7: 1497 | I7: =IF(DatiOriginali!I7 >= SogliaPicchi!$B$2,"",DatiOriginali!I7) -> 141800 | J7: 1587 | K7: =IF(DatiOriginali!K7 >= SogliaPicchi!$B$2,"",DatiOriginali!K7) -> 143800
A8: seq_50_6 | B8: 1225 | C8: =IF(DatiOriginali!C8 >= SogliaPicchi!$B$2,"",DatiOriginali!C8) -> 408500 | D8: 562 | E8: =IF(DatiOriginali!E8 >= SogliaPicchi!$B$2,"",DatiOriginali!E8) -> 168900 | F8: 1560 | G8: =IF(DatiOriginali!G8 >= SogliaPicchi!$B$2,"",DatiOriginali!G8) -> 64400 | H8: 1784 | I8: =IF(DatiOriginali!I8 >= SogliaPicchi!$B$2,"",DatiOriginali!I8) -> 187900 | J8: 1843 | K8: =IF(DatiOriginali!K8 >= SogliaPicchi!$B$2,"",DatiOriginali!K8) -> 185900
A9: seq_50_7 | B9: 1225 | C9: =IF(DatiOriginali!C9 >= SogliaPicchi!$B$2,"",DatiOriginali!C9) -> 302100 | D9: 615 | E9: =IF(DatiOriginali!E9 >= SogliaPicchi!$B$2,"",DatiOriginali!E9) -> 120000 | F9: 1778 | G9: =IF(DatiOriginali!G9 >= SogliaPicchi!$B$2,"",DatiOriginali!G9) -> 99800 | H9: 2047 | I9: =IF(DatiOriginali!I9 >= SogliaPicchi!$B$2,"",DatiOriginali!I9) -> 81400 | J9: 2113 | K9: =IF(DatiOriginali!K9 >= SogliaPicchi!$B$2,"",DatiOriginali!K9) -> 92900
A10: seq_50_8 | B10: 1225 | C10: =IF(DatiOriginali!C10 >= SogliaPicchi!$B$2,"",DatiOriginali!C10) -> 290700 | D10: 629 | E10: =IF(DatiOriginali!E10 >= SogliaPicchi!$B$2,"",DatiOriginali!E10) -> 118300 | F10: 1997 | G10: =IF(DatiOriginali!G10 >= SogliaPicchi!$B$2,"",DatiOriginali!G10) -> 32400 | H10: 2301 | I10: =IF(DatiOriginali!I10 >= SogliaPicchi!$B$2,"",DatiOriginali!I10) -> 75800 | J10: 2338 | K10: =IF(DatiOriginali!K10 >= SogliaPicchi!$B$2,"",DatiOriginali!K10) -> 75800
A11: seq_50_9 | B11: 1225 | C11: =IF(DatiOriginali!C11 >= SogliaPicchi!$B$2,"",DatiOriginali!C11) -> 533700 | D11: 743 | E11: =IF(DatiOriginali!E11 >= SogliaPicchi!$B$2,"",DatiOriginali!E11) -> 213800 | F11: 2217 | G11: =IF(DatiOriginali!G11 >= SogliaPicchi!$B$2,"",DatiOriginali!G11) -> 62700 | H11: 2565 | I11: =IF(DatiOriginali!I11 >= SogliaPicchi!$B$2,"",DatiOriginali!I11) -> 98400 | J11: 2569 | K11: =IF(DatiOriginali!K11 >= SogliaPicchi!$B$2,"",DatiOriginali!K11) -> 113600
A12: seq_50_10 | B12: 1225 | C12: =IF(DatiOriginali!C12 >= SogliaPicchi!$B$2,"",DatiOriginali!C12) -> 436900 | D12: 687 | E12: =IF(DatiOriginali!E12 >= SogliaPicchi!$B$2,"",DatiOriginali!E12) -> 198700 | F12: 2437 | G12: =IF(DatiOriginali!G12 >= SogliaPicchi!$B$2,"",DatiOriginali!G12) -> 59400 | H12: 2813 | I12: =IF(DatiOriginali!I12 >= SogliaPicchi!$B$2,"",DatiOriginali!I12) -> 103200 | J12: 2828 | K12: =IF(DatiOriginali!K12 >= SogliaPicchi!$B$2,"",DatiOriginali!K12) -> 120600
A13: seq_50_11 | B13: 1225 | C13: =IF(DatiOriginali!C13 >= SogliaPicchi!$B$2,"",DatiOriginali!C13) -> 438200 | D13: 600 | E13: =IF(DatiOriginali!E13 >= SogliaPicchi!$B$2,"",DatiOriginali!E13) -> 173700 | F13: 2658 | G13: =IF(DatiOriginali!G13 >= SogliaPicchi!$B$2,"",DatiOriginali!G13) -> 76100 | H13: 3082 | I13: =IF(DatiOriginali!I13 >= SogliaPicchi!$B$2,"",DatiOriginali!I13) -> 105800 | J13: 3114 | K13: =IF(DatiOriginali!K13 >= SogliaPicchi!$B$2,"",DatiOriginali!K13) -> 110800
... A100: seq_50_98 | B100: 1225 | C100: =IF(DatiOriginali!C100 >= SogliaPicchi!$B$2,"",DatiOriginali!C100) -> 43800 | D100: 596 | E100: =IF(DatiOriginali!E100 >= SogliaPicchi!$B$2,"",DatiOriginali!E100) -> 18000 | F100: 21978 | G100: =IF(DatiOriginali!G100 >= SogliaPicchi!$B$2,"",DatiOriginali!G100) -> 148100 | H100: 25812 | I100: =IF(DatiOriginali!I100 >= SogliaPicchi!$B$2,"",DatiOriginali!I100) -> 66000 | J100: 25538 | K100: =IF(DatiOriginali!K100 >= SogliaPicchi!$B$2,"",DatiOriginali!K100) -> 79500
A101: seq_50_99 | B101: 1225 | C101: =IF(DatiOriginali!C101 >= SogliaPicchi!$B$2,"",DatiOriginali!C101) -> 108400 | D101: 599 | E101: =IF(DatiOriginali!E101 >= SogliaPicchi!$B$2,"",DatiOriginali!E101) -> 42600 | F101: 22200 | G101: =IF(DatiOriginali!G101 >= SogliaPicchi!$B$3,"",DatiOriginali!G101) | H101: 26083 | I101: =IF(DatiOriginali!I101 >= SogliaPicchi!$B$3,"",DatiOriginali!I101) | J101: 25814 | K101: =IF(DatiOriginali!K101 >= SogliaPicchi!$B$3,"",DatiOriginali!K101)
A102: seq_100_0 | B102: 4950 | C102: =IF(DatiOriginali!C102 >= SogliaPicchi!$B$3,"",DatiOriginali!C102) | D102: 2639 | E102: =IF(DatiOriginali!E102 >= SogliaPicchi!$B$3,"",DatiOriginali!E102) | F102: 22744 | G102: =IF(DatiOriginali!G102 >= SogliaPicchi!$B$3,"",DatiOriginali!G102) | H102: 26734 | I102: =IF(DatiOriginali!I102 >= SogliaPicchi!$B$3,"",DatiOriginali!I102) | J102: 26491 | K102: =IF(DatiOriginali!K102 >= SogliaPicchi!$B$3,"",DatiOriginali!K102)
A103: seq_100_1 | B103: 4950 | C103: =IF(DatiOriginali!C103 >= SogliaPicchi!$B$3,"",DatiOriginali!C103) | D103: =IF(DatiOriginali!D103 >= SogliaPicchi!$B$3,"",DatiOriginali!D103) -> 2481 | E103: =IF(DatiOriginali!E103 >= SogliaPicchi!$B$3,"",DatiOriginali!E103) | F103: 23287 | G103: =IF(DatiOriginali!G103 >= SogliaPicchi!$B$3,"",DatiOriginali!G103) | H103: 27371 | I103: =IF(DatiOriginali!I103 >= SogliaPicchi!$B$3,"",DatiOriginali!I103) | J103: 27148 | K103: =IF(DatiOriginali!K103 >= SogliaPicchi!$B$3,"",DatiOriginali!K103)
A104: seq_100_2 | B104: 4950 | C104: =IF(DatiOriginali!C104 >= SogliaPicchi!$B$3,"",DatiOriginali!C104) | D104: =IF(DatiOriginali!D104 >= SogliaPicchi!$B$3,"",DatiOriginali!D104) -> 2684 | E104: =IF(DatiOriginali!E104 >= SogliaPicchi!$B$3,"",DatiOriginali!E104) | F104: 23828 | G104: =IF(DatiOriginali!G104 >= SogliaPicchi!$B$3,"",DatiOriginali!G104) | H104: 27973 | I104: =IF(DatiOriginali!I104 >= SogliaPicchi!$B$3,"",DatiOriginali!I104) | J104: 27828 | K104: =IF(DatiOriginali!K104 >= SogliaPicchi!$B$3,"",DatiOriginali!K104)
A105: seq_100_3 | B105: 4950 | C105: =IF(DatiOriginali!C105 >= SogliaPicchi!$B$3,"",DatiOriginali!C105) | D105: =IF(DatiOriginali!D105 >= SogliaPicchi!$B$3,"",DatiOriginali!D105) -> 2603 | E105: =IF(DatiOriginali!E105 >= SogliaPicchi!$B$3,"",DatiOriginali!E105) -> 73100 | F105: 24372 | G105: =IF(DatiOriginali!G105 >= SogliaPicchi!$B$3,"",DatiOriginali!G105) | H105: 28623 | I105: =IF(DatiOriginali!I105 >= SogliaPicchi!$B$3,"",DatiOriginali!I105) -> 34200 | J105: 28493 | K105: =IF(DatiOriginali!K105 >= SogliaPicchi!$B$3,"",DatiOriginali!K105)
A106: seq_100_4 | B106: 4950 | C106: =IF(DatiOriginali!C106 >= SogliaPicchi!$B$3,"",DatiOriginali!C106) | D106: =IF(DatiOriginali!D106 >= SogliaPicchi!$B$3,"",DatiOriginali!D106) -> 2946 | E106: =IF(DatiOriginali!E106 >= SogliaPicchi!$B$3,"",DatiOriginali!E106) | F106: 24913 | G106: =IF(DatiOriginali!G106 >= SogliaPicchi!$B$3,"",DatiOriginali!G106) | H106: 29315 | I106: =IF(DatiOriginali!I106 >= SogliaPicchi!$B$3,"",DatiOriginali!I106) -> 15700 | J106: 29198 | K106: =IF(DatiOriginali!K106 >= SogliaPicchi!$B$3,"",DatiOriginali!K106)
A107: seq_100_5 | B107: 4950 | C107: =IF(DatiOriginali!C107 >= SogliaPicchi!$B$3,"",DatiOriginali!C107) | D107: 2325 | E107: 132400 | F107: 25451 | G107: =IF(DatiOriginali!G107 >= SogliaPicchi!$B$3,"",DatiOriginali!G107) | H107: 29992 | I107: =IF(DatiOriginali!I107 >= SogliaPicchi!$B$3,"",DatiOriginali!I107) -> 13000 | J107: 29809 | K107: =IF(DatiOriginali!K107 >= SogliaPicchi!$B$3,"",DatiOriginali!K107)
A108: seq_100_6 | B108: 4950 | C108: =IF(DatiOriginali!C108 >= SogliaPicchi!$B$3,"",DatiOriginali!C108) | D108: 2399 | E108: =IF(DatiOriginali!E108 >= SogliaPicchi!$B$3,"",DatiOriginali!E108) | F108: =IF(DatiOriginali!F108 >= SogliaPicchi!$B$3,"",DatiOriginali!F108) -> 25989 | G108: =IF(DatiOriginali!G108 >= SogliaPicchi!$B$3,"",DatiOriginali!G108) | H108: 30664 | I108: =IF(DatiOriginali!I108 >= SogliaPicchi!$B$3,"",DatiOriginali!I108) -> 18000 | J108: 30406 | K108: =IF(DatiOriginali!K108 >= SogliaPicchi!$B$3,"",DatiOriginali!K108)
A109: seq_100_7 | B109: 4950 | C109: =IF(DatiOriginali!C109 >= SogliaPicchi!$B$3,"",DatiOriginali!C109) | D109: 2583 | E109: =IF(DatiOriginali!E109 >= SogliaPicchi!$B$3,"",DatiOriginali!E109) | F109: 26529 | G109: =IF(DatiOriginali!G109 >= SogliaPicchi!$B$3,"",DatiOriginali!G109) -> 48600 | H109: 31304 | I109: =IF(DatiOriginali!I109 >= SogliaPicchi!$B$3,"",DatiOriginali!I109) -> 12400 | J109: 31056 | K109: =IF(DatiOriginali!K109 >= SogliaPicchi!$B$3,"",DatiOriginali!K109)
A110: seq_100_8 | B110: 4950 | C110: =IF(DatiOriginali!C110 >= SogliaPicchi!$B$3,"",DatiOriginali!C110) | D110: 2559 | E110: =IF(DatiOriginali!E110 >= SogliaPicchi!$B$3,"",DatiOriginali!E110) -> 71700 | F110: 27069 | G110: =IF(DatiOriginali!G110 >= SogliaPicchi!$B$3,"",DatiOriginali!G110) -> 44100 | H110: 31903 | I110: =IF(DatiOriginali!I110 >= SogliaPicchi!$B$3,"",DatiOriginali!I110) -> 9900 | J110: 31763 | K110: =IF(DatiOriginali!K110 >= SogliaPicchi!$B$3,"",DatiOriginali!K110)
A111: seq_100_9 | B111: 4950 | C111: =IF(DatiOriginali!C111 >= SogliaPicchi!$B$3,"",DatiOriginali!C111) | D111: 2616 | E111: =IF(DatiOriginali!E111 >= SogliaPicchi!$B$3,"",DatiOriginali!E111) | F111: 27608 | G111: =IF(DatiOriginali!G111 >= SogliaPicchi!$B$3,"",DatiOriginali!G111) -> 53200 | H111: 32515 | I111: =IF(DatiOriginali!I111 >= SogliaPicchi!$B$3,"",DatiOriginali!I111) -> 14000 | J111: 32539 | K111: =IF(DatiOriginali!K111 >= SogliaPicchi!$B$3,"",DatiOriginali!K111) -> 69800
A112: seq_100_10 | B112: 4950 | C112: =IF(DatiOriginali!C112 >= SogliaPicchi!$B$3,"",DatiOriginali!C112) | D112: 2802 | E112: =IF(DatiOriginali!E112 >= SogliaPicchi!$B$3,"",DatiOriginali!E112) | F112: 28154 | G112: =IF(DatiOriginali!G112 >= SogliaPicchi!$B$3,"",DatiOriginali!G112) -> 51600 | H112: 33247 | I112: =IF(DatiOriginali!I112 >= SogliaPicchi!$B$3,"",DatiOriginali!I112) -> 12500 | J112: 33349 | K112: =IF(DatiOriginali!K112 >= SogliaPicchi!$B$3,"",DatiOriginali!K112) -> 17100
A113: seq_100_11 | B113: 4950 | C113: =IF(DatiOriginali!C113 >= SogliaPicchi!$B$3,"",DatiOriginali!C113) | D113: 2506 | E113: =IF(DatiOriginali!E113 >= SogliaPicchi!$B$3,"",DatiOriginali!E113) | F113: 28692 | G113: =IF(DatiOriginali!G113 >= SogliaPicchi!$B$3,"",DatiOriginali!G113) -> 51500 | H113: 33917 | I113: =IF(DatiOriginali!I113 >= SogliaPicchi!$B$3,"",DatiOriginali!I113) -> 16000 | J113: 34135 | K113: =IF(DatiOriginali!K113 >= SogliaPicchi!$B$3,"",DatiOriginali!K113) -> 21700
A114: seq_100_12 | B114: 4950 | C114: =IF(DatiOriginali!C114 >= SogliaPicchi!$B$3,"",DatiOriginali!C114) | D114: 2402 | E114: =IF(DatiOriginali!E114 >= SogliaPicchi!$B$3,"",DatiOriginali!E114) | F114: 29239 | G114: =IF(DatiOriginali!G114 >= SogliaPicchi!$B$3,"",DatiOriginali!G114) -> 36700 | H114: 34591 | I114: =IF(DatiOriginali!I114 >= SogliaPicchi!$B$3,"",DatiOriginali!I114) -> 10400 | J114: 34772 | K114: =IF(DatiOriginali!K114 >= SogliaPicchi!$B$3,"",DatiOriginali!K114) -> 13000
A115: seq_100_13 | B115: 4950 | C115: =IF(DatiOriginali!C115 >= SogliaPicchi!$B$3,"",DatiOriginali!C115) | D115: 2825 | E115: =IF(DatiOriginali!E115 >= SogliaPicchi!$B$3,"",DatiOriginali!E115) | F115: 29786 | G115: =IF(DatiOriginali!G115 >= SogliaPicchi!$B$3,"",DatiOriginali!G115) -> 45200 | H115: 35273 | I115: =IF(DatiOriginali!I115 >= SogliaPicchi!$B$3,"",DatiOriginali!I115) -> 10600 | J115: 35468 | K115: =IF(DatiOriginali!K115 >= SogliaPicchi!$B$3,"",DatiOriginali!K115) -> 12700
A116: seq_100_14 | B116: 4950 | C116: =IF(DatiOriginali!C116 >= SogliaPicchi!$B$3,"",DatiOriginali!C116) | D116: 2488 | E116: =IF(DatiOriginali!E116 >= SogliaPicchi!$B$3,"",DatiOriginali!E116) -> 69500 | F116: 30325 | G116: =IF(DatiOriginali!G116 >= SogliaPicchi!$B$3,"",DatiOriginali!G116) -> 33500 | H116: 36035 | I116: =IF(DatiOriginali!I116 >= SogliaPicchi!$B$3,"",DatiOriginali!I116) -> 32200 | J116: 36078 | K116: =IF(DatiOriginali!K116 >= SogliaPicchi!$B$3,"",DatiOriginali!K116) -> 30200
A117: seq_100_15 | B117: 4950 | C117: =IF(DatiOriginali!C117 >= SogliaPicchi!$B$3,"",DatiOriginali!C117) | D117: 2582 | E117: =IF(DatiOriginali!E117 >= SogliaPicchi!$B$3,"",DatiOriginali!E117) -> 72100 | F117: 30868 | G117: =IF(DatiOriginali!G117 >= SogliaPicchi!$B$3,"",DatiOriginali!G117) -> 31000 | H117: 36675 | I117: =IF(DatiOriginali!I117 >= SogliaPicchi!$B$3,"",DatiOriginali!I117) -> 9500 | J117: 36829 | K117: =IF(DatiOriginali!K117 >= SogliaPicchi!$B$3,"",DatiOriginali!K117) -> 12800
A118: seq_100_16 | B118: 4950 | C118: =IF(DatiOriginali!C118 >= SogliaPicchi!$B$3,"",DatiOriginali!C118) | D118: 2408 | E118: =IF(DatiOriginali!E118 >= SogliaPicchi!$B$3,"",DatiOriginali!E118) | F118: 31403 | G118: =IF(DatiOriginali!G118 >= SogliaPicchi!$B$3,"",DatiOriginali!G118) -> 62700 | H118: 37243 | I118: =IF(DatiOriginali!I118 >= SogliaPicchi!$B$3,"",DatiOriginali!I118) -> 15000 | J118: 37392 | K118: =IF(DatiOriginali!K118 >= SogliaPicchi!$B$3,"",DatiOriginali!K118) -> 19000
A119: seq_100_17 | B119: 4950 | C119: =IF(DatiOriginali!C119 >= SogliaPicchi!$B$3,"",DatiOriginali!C119) | D119: 2271 | E119: =IF(DatiOriginali!E119 >= SogliaPicchi!$B$3,"",DatiOriginali!E119) | F119: 31950 | G119: =IF(DatiOriginali!G119 >= SogliaPicchi!$B$3,"",DatiOriginali!G119) -> 52900 | H119: 37999 | I119: =IF(DatiOriginali!I119 >= SogliaPicchi!$B$3,"",DatiOriginali!I119) -> 16300 | J119: 37976 | K119: =IF(DatiOriginali!K119 >= SogliaPicchi!$B$3,"",DatiOriginali!K119) -> 20200
A120: seq_100_18 | B120: 4950 | C120: =IF(DatiOriginali!C120 >= SogliaPicchi!$B$3,"",DatiOriginali!C120) | D120: 2588 | E120: =IF(DatiOriginali!E120 >= SogliaPicchi!$B$3,"",DatiOriginali!E120) -> 73500 | F120: 32494 | G120: =IF(DatiOriginali!G120 >= SogliaPicchi!$B$3,"",DatiOriginali!G120) -> 33500 | H120: 38677 | I120: =IF(DatiOriginali!I120 >= SogliaPicchi!$B$3,"",DatiOriginali!I120) -> 11000 | J120: 38611 | K120: =IF(DatiOriginali!K120 >= SogliaPicchi!$B$3,"",DatiOriginali!K120) -> 14300
... A200: seq_100_98 | B200: 4950 | C200: =IF(DatiOriginali!C200 >= SogliaPicchi!$B$3,"",DatiOriginali!C200) -> 43900 | D200: 2562 | E200: =IF(DatiOriginali!E200 >= SogliaPicchi!$B$3,"",DatiOriginali!E200) -> 18800 | F200: 75768 | G200: =IF(DatiOriginali!G200 >= SogliaPicchi!$B$3,"",DatiOriginali!G200) -> 50200 | H200: 90882 | I200: =IF(DatiOriginali!I200 >= SogliaPicchi!$B$3,"",DatiOriginali!I200) -> 13400 | J200: 90764 | K200: =IF(DatiOriginali!K200 >= SogliaPicchi!$B$3,"",DatiOriginali!K200) -> 16600
A201: seq_100_99 | B201: 4950 | C201: =IF(DatiOriginali!C201 >= SogliaPicchi!$B$3,"",DatiOriginali!C201) -> 41600 | D201: 2322 | E201: =IF(DatiOriginali!E201 >= SogliaPicchi!$B$3,"",DatiOriginali!E201) -> 16200 | F201: 76305 | G201: =IF(DatiOriginali!G201 >= SogliaPicchi!$B$4,"",DatiOriginali!G201) -> 49000 | H201: 91469 | I201: =IF(DatiOriginali!I201 >= SogliaPicchi!$B$4,"",DatiOriginali!I201) -> 12300 | J201: 91442 | K201: =IF(DatiOriginali!K201 >= SogliaPicchi!$B$4,"",DatiOriginali!K201) -> 15700
A202: seq_150_0 | B202: 11175 | C202: =IF(DatiOriginali!C202 >= SogliaPicchi!$B$4,"",DatiOriginali!C202) -> 92000 | D202: 5541 | E202: =IF(DatiOriginali!E202 >= SogliaPicchi!$B$4,"",DatiOriginali!E202) -> 36500 | F202: 77203 | G202: =IF(DatiOriginali!G202 >= SogliaPicchi!$B$4,"",DatiOriginali!G202) -> 95000 | H202: 92464 | I202: =IF(DatiOriginali!I202 >= SogliaPicchi!$B$4,"",DatiOriginali!I202) -> 20200 | J202: 92400 | K202: =IF(DatiOriginali!K202 >= SogliaPicchi!$B$4,"",DatiOriginali!K202) -> 23300
A203: seq_150_1 | B203: 11175 | C203: =IF(DatiOriginali!C203 >= SogliaPicchi!$B$4,"",DatiOriginali!C203) -> 94500 | D203: 5611 | E203: =IF(DatiOriginali!E203 >= SogliaPicchi!$B$4,"",DatiOriginali!E203) -> 38400 | F203: 78104 | G203: =IF(DatiOriginali!G203 >= SogliaPicchi!$B$4,"",DatiOriginali!G203) -> 95800 | H203: 93521 | I203: =IF(DatiOriginali!I203 >= SogliaPicchi!$B$4,"",DatiOriginali!I203) -> 20300 | J203: 93628 | K203: =IF(DatiOriginali!K203 >= SogliaPicchi!$B$4,"",DatiOriginali!K203) -> 24800
A204: seq_150_2 | B204: 11175 | C204: =IF(DatiOriginali!C204 >= SogliaPicchi!$B$4,"",DatiOriginali!C204) -> 91600 | D204: 5605 | E204: =IF(DatiOriginali!E204 >= SogliaPicchi!$B$4,"",DatiOriginali!E204) -> 37400 | F204: 79006 | G204: =IF(DatiOriginali!G204 >= SogliaPicchi!$B$4,"",DatiOriginali!G204) -> 77300 | H204: 94553 | I204: =IF(DatiOriginali!I204 >= SogliaPicchi!$B$4,"",DatiOriginali!I204) -> 27600 | J204: 94713 | K204: =IF(DatiOriginali!K204 >= SogliaPicchi!$B$4,"",DatiOriginali!K204) -> 24200
A205: seq_150_3 | B205: 11175 | C205: =IF(DatiOriginali!C205 >= SogliaPicchi!$B$4,"",DatiOriginali!C205) -> 68600 | D205: 5805 | E205: =IF(DatiOriginali!E205 >= SogliaPicchi!$B$4,"",DatiOriginali!E205) -> 24600 | F205: 79890 | G205: =IF(DatiOriginali!G205 >= SogliaPicchi!$B$4,"",DatiOriginali!G205) -> 61800 | H205: 95982 | I205: =IF(DatiOriginali!I205 >= SogliaPicchi!$B$4,"",DatiOriginali!I205) -> 19700 | J205: 95636 | K205: =IF(DatiOriginali!K205 >= SogliaPicchi!$B$4,"",DatiOriginali!K205) -> 19700
...

Sheet Min
A1: n | B1: ConfrontiOttimoBS | C1: TnsOttimoBS | D1: ConfrontiOttimoIS | E1: TnsOttimoIS | F1: ConfrontiOttimoMS | G1: TnsOttimoMS | H1: ConfrontiOttimoQS | I1: TnsOttimoQS | J1: ConfrontiOttimoQSR | K1: TnsOttimoQSR
A2: 50 | B2: =MIN(DatiRipuliti!B2:B101) -> 1225 | C2: =MIN(DatiRipuliti!C2:C101) -> 43100 | D2: =MIN(DatiRipuliti!D2:D101) -> 544 | E2: =MIN(DatiRipuliti!E2:E101) -> 17100 | F2: =MIN(DatiRipuliti!F2:F101) -> 226 | G2: =MIN(DatiRipuliti!G2:G101) -> 29100 | H2: =MIN(DatiRipuliti!H2:H101) -> 216 | I2: =MIN(DatiRipuliti!I2:I101) -> 10800 | ... K2: =MIN(DatiRipuliti!K2:K101) -> 12500
A3: 100 | B3: =MIN(DatiRipuliti!B102:B201) -> 4950 | C3: =MIN(DatiRipuliti!C102:C201) -> 32300 | D3: =MIN(DatiRipuliti!D102:D201) -> 2125 | E3: =MIN(DatiRipuliti!E102:E201) -> 10800 | F3: =MIN(DatiRipuliti!F102:F201) -> 22744 | G3: =MIN(DatiRipuliti!G102:G201) -> 30600 | H3: =MIN(DatiRipuliti!H102:H201) -> 26734 | I3: =MIN(DatiRipuliti!I102:I201) -> 9000 | ... K3: =MIN(DatiRipuliti!K102:K201) -> 10900
A4: 150 | B4: =MIN(DatiRipuliti!B202:B301) -> 11175 | C4: =MIN(DatiRipuliti!C202:C301) -> 63700 | D4: =MIN(DatiRipuliti!D202:D301) -> 5076 | E4: =MIN(DatiRipuliti!E202:E301) -> 20900 | F4: =MIN(DatiRipuliti!F202:F301) -> 77203 | G4: =MIN(DatiRipuliti!G202:G301) -> 43900 | H4: =MIN(DatiRipuliti!H202:H301) -> 92464 | I4: =MIN(DatiRipuliti!I202:I301) -> 13500 | ... K4: =MIN(DatiRipuliti!K202:K301) -> 16800
A5: 200 | B5: =MIN(DatiRipuliti!B302:B401) -> 19900 | C5: =MIN(DatiRipuliti!C302:C401) -> 113700 | D5: =MIN(DatiRipuliti!D302:D401) -> 9108 | E5: =MIN(DatiRipuliti!E302:E401) -> 34800 | F5: =MIN(DatiRipuliti!F302:F401) -> 167451 | G5: =MIN(DatiRipuliti!G302:G401) -> 61100 | H5: =MIN(DatiRipuliti!H302:H401) -> 201247 | I5: =MIN(DatiRipuliti!I302:I401) -> 19000 | ... K5: =MIN(DatiRipuliti!K302:K401) -> 21900
A6: 250 | B6: =MIN(DatiRipuliti!B402:B501) -> 31125 | C6: =MIN(DatiRipuliti!C402:C501) -> 181800 | D6: =MIN(DatiRipuliti!D402:D501) -> 14401 | E6: =MIN(DatiRipuliti!E402:E501) -> 53900 | F6: =MIN(DatiRipuliti!F402:F501) -> 295965 | G6: =MIN(DatiRipuliti!G402:G501) -> 78600 | H6: =MIN(DatiRipuliti!H402:H501) -> 358596 | I6: =MIN(DatiRipuliti!I402:I501) -> 24000 | ... K6: =MIN(DatiRipuliti!K402:K501) -> 27600
A7: 300 | B7: =MIN(DatiRipuliti!B502:B601) -> 44850 | C7: =MIN(DatiRipuliti!C502:C601) -> 262800 | D7: =MIN(DatiRipuliti!D502:D601) -> 20801 | E7: =MIN(DatiRipuliti!E502:E601) -> 77700 | F7: =MIN(DatiRipuliti!F502:F601) -> 464143 | G7: =MIN(DatiRipuliti!G502:G601) -> 97600 | H7: =MIN(DatiRipuliti!H502:H601) -> 567304 | I7: =MIN(DatiRipuliti!I502:I601) -> 30600 | ... K7: =MIN(DatiRipuliti!K502:K601) -> 34600
A8: 350 | B8: =MIN(DatiRipuliti!B602:B701) -> 61075 | C8: =MIN(DatiRipuliti!C602:C701) -> 370100 | D8: =MIN(DatiRipuliti!D602:D701) -> 27982 | E8: =MIN(DatiRipuliti!E602:E701) -> 102500 | F8: =MIN(DatiRipuliti!F602:F701) -> 674352 | G8: =MIN(DatiRipuliti!G602:G701) -> 113800 | H8: =MIN(DatiRipuliti!H602:H701) -> 825560 | I8: =MIN(DatiRipuliti!I602:I701) -> 36000 | ... K8: =MIN(DatiRipuliti!K602:K701) -> 39600
A9: 400 | B9: =MIN(DatiRipuliti!B702:B801) -> 79800 | C9: =MIN(DatiRipuliti!C702:C801) -> 479900 | D9: =MIN(DatiRipuliti!D702:D801) -> 37671 | E9: =MIN(DatiRipuliti!E702:E801) -> 134000 | F9: =MIN(DatiRipuliti!F702:F801) -> 927307 | G9: =MIN(DatiRipuliti!G702:G801) -> 131700 | H9: =MIN(DatiRipuliti!H702:H801) -> 1138986 | I9: =MIN(DatiRipuliti!I702:I801) -> 42400 | ... K9: =MIN(DatiRipuliti!K702:K801) -> 47200
A10: 450 | B10: =MIN(DatiRipuliti!B802:B901) -> 101025 | C10: =MIN(DatiRipuliti!C802:C901) -> 608900 | D10: =MIN(DatiRipuliti!D802:D901) -> 47713 | E10: =MIN(DatiRipuliti!E802:E901) -> 170500 | F10: =MIN(DatiRipuliti!F802:F901) -> 1223897 | G10: =MIN(DatiRipuliti!G802:G901) -> 148400 | H10: =MIN(DatiRipuliti!H802:H901) -> 1511744 | I10: =MIN(DatiRipuliti!I802:I901) -> 47200 | ... K10: =MIN(DatiRipuliti!K802:K901) -> 53100
A11: 500 | B11: =MIN(DatiRipuliti!B902:B1001) -> 124750 | C11: =MIN(DatiRipuliti!C902:C1001) -> 774500 | D11: =MIN(DatiRipuliti!D902:D1001) -> 59041 | E11: =MIN(DatiRipuliti!E902:E1001) -> 211600 | F11: =MIN(DatiRipuliti!F902:F1001) -> 1564994 | G11: =MIN(DatiRipuliti!G902:G1001) -> 168600 | H11: =MIN(DatiRipuliti!H902:H1001) -> 1935733 | I11: =MIN(DatiRipuliti!I902:I1001) -> 54300 | ... K11: =MIN(DatiRipuliti!K902:K1001) -> 62100
A12: 550 | B12: =MIN(DatiRipuliti!B1002:B1101) -> 150975 | C12: =MIN(DatiRipuliti!C1002:C1101) -> 963000 | D12: =MIN(DatiRipuliti!D1002:D1101) -> 70914 | E12: =MIN(DatiRipuliti!E1002:E1101) -> 255400 | F12: =MIN(DatiRipuliti!F1002:F1101) -> 1950689 | G12: =MIN(DatiRipuliti!G1002:G1101) -> 187700 | H12: =MIN(DatiRipuliti!H1002:H1101) -> 2413055 | I12: =MIN(DatiRipuliti!I1002:I1101) -> 59800 | ... K12: =MIN(DatiRipuliti!K1002:K1101) -> 68300
A13: 600 | B13: =MIN(DatiRipuliti!B1102:B1201) -> 179700 | C13: =MIN(DatiRipuliti!C1102:C1201) -> 1194700 | D13: =MIN(DatiRipuliti!D1102:D1201) -> 84650 | E13: =MIN(DatiRipuliti!E1102:E1201) -> 296000 | F13: =MIN(DatiRipuliti!F1102:F1201) -> 2383056 | G13: =MIN(DatiRipuliti!G1102:G1201) -> 206500 | H13: =MIN(DatiRipuliti!H1102:H1201) -> 2954344 | I13: =MIN(DatiRipuliti!I1102:I1201) -> 67100 | ... K13: =MIN(DatiRipuliti!K1102:K1201) -> 75100
A14: 650 | B14: =MIN(DatiRipuliti!B1202:B1301) -> 210925 | C14: =MIN(DatiRipuliti!C1202:C1301) -> 1458500 | D14: =MIN(DatiRipuliti!D1202:D1301) -> 97200 | E14: =MIN(DatiRipuliti!E1202:E1301) -> 339400 | F14: =MIN(DatiRipuliti!F1202:F1301) -> 2862911 | G14: =MIN(DatiRipuliti!G1202:G1301) -> 224200 | H14: =MIN(DatiRipuliti!H1202:H1301) -> 3557288 | I14: =MIN(DatiRipuliti!I1202:I1301) -> 73700 | ... K14: =MIN(DatiRipuliti!K1202:K1301) -> 83100
A15: 700 | B15: =MIN(DatiRipuliti!B1302:B1401) -> 244650 | C15: =MIN(DatiRipuliti!C1302:C1401) -> 1740000 | D15: =MIN(DatiRipuliti!D1302:D1401) -> 115188 | E15: =MIN(DatiRipuliti!E1302:E1401) -> 401200 | F15: =MIN(DatiRipuliti!F1302:F1401) -> 3390210 | G15: =MIN(DatiRipuliti!G1302:G1401) -> 244400 | H15: =MIN(DatiRipuliti!H1302:H1401) -> 4219278 | I15: =MIN(DatiRipuliti!I1302:I1401) -> 79800 | ... K15: =MIN(DatiRipuliti!K1302:K1401) -> 89700
A16: 750 | B16: =MIN(DatiRipuliti!B1402:B1501) -> 280875 | C16: =MIN(DatiRipuliti!C1402:C1501) -> 1968200 | D16: =MIN(DatiRipuliti!D1402:D1501) -> 129878 | E16: =MIN(DatiRipuliti!E1402:E1501) -> 455100 | F16: =MIN(DatiRipuliti!F1402:F1501) -> 3965709 | G16: =MIN(DatiRipuliti!G1402:G1501) -> 266300 | H16: =MIN(DatiRipuliti!H1402:H1501) -> 4935740 | I16: =MIN(DatiRipuliti!I1402:I1501) -> 87300 | ... K16: =MIN(DatiRipuliti!K1402:K1501) -> 96700
A17: 800 | B17: =MIN(DatiRipuliti!B1502:B1601) -> 319600 | C17: =MIN(DatiRipuliti!C1502:C1601) -> 2324000 | D17: =MIN(DatiRipuliti!D1502:D1601) -> 150497 | E17: =MIN(DatiRipuliti!E1502:E1601) -> 524500 | F17: =MIN(DatiRipuliti!F1502:F1601) -> 4589564 | G17: =MIN(DatiRipuliti!G1502:G1601) -> 286800 | H17: =MIN(DatiRipuliti!H1502:H1601) -> 5722286 | I17: =MIN(DatiRipuliti!I1502:I1601) -> 94700 | ... K17: =MIN(DatiRipuliti!K1502:K1601) -> 104400
A18: 850 | B18: =MIN(DatiRipuliti!B1602:B1701) -> 360825 | C18: =MIN(DatiRipuliti!C1602:C1701) -> 2638100 | D18: =MIN(DatiRipuliti!D1602:D1701) -> 172049 | E18: =MIN(DatiRipuliti!E1602:E1701) -> 606300 | F18: =MIN(DatiRipuliti!F1602:F1701) -> 5262512 | G18: =MIN(DatiRipuliti!G1602:G1701) -> 306500 | H18: =MIN(DatiRipuliti!H1602:H1701) -> 6560817 | I18: =MIN(DatiRipuliti!I1602:I1701) -> 101600 | ... K18: =MIN(DatiRipuliti!K1602:K1701) -> 111500
A19: 900 | B19: =MIN(DatiRipuliti!B1702:B1801) -> 404550 | C19: =MIN(DatiRipuliti!C1702:C1801) -> 3095100 | D19: =MIN(DatiRipuliti!D1702:D1801) -> 193118 | E19: =MIN(DatiRipuliti!E1702:E1801) -> 668500 | F19: =MIN(DatiRipuliti!F1702:F1801) -> 5984400 | G19: =MIN(DatiRipuliti!G1702:G1801) -> 322400 | H19: =MIN(DatiRipuliti!H1702:H1801) -> 7467881 | I19: =MIN(DatiRipuliti!I1702:I1801) -> 107400 | ... K19: =MIN(DatiRipuliti!K1702:K1801) -> 120900
A20: 950 | B20: =MIN(DatiRipuliti!B1802:B1901) -> 450775 | C20: =MIN(DatiRipuliti!C1802:C1901) -> 3423000 | D20: =MIN(DatiRipuliti!D1802:D1901) -> 215136 | E20: =MIN(DatiRipuliti!E1802:E1901) -> 743300 | F20: =MIN(DatiRipuliti!F1802:F1901) -> 6755660 | G20: =MIN(DatiRipuliti!G1802:G1901) -> 345100 | H20: =MIN(DatiRipuliti!H1802:H1901) -> 8432250 | I20: =MIN(DatiRipuliti!I1802:I1901) -> 114700 | ... K20: =MIN(DatiRipuliti!K1802:K1901) -> 126000
A21: 1000 | B21: =MIN(DatiRipuliti!B1902:B2001) -> 499500 | C21: =MIN(DatiRipuliti!C1902:C2001) -> 3939000 | D21: =MIN(DatiRipuliti!D1902:D2001) -> 239293 | E21: =MIN(DatiRipuliti!E1902:E2001) -> 830500 | F21: =MIN(DatiRipuliti!F1902:F2001) -> 7576926 | G21: =MIN(DatiRipuliti!G1902:G2001) -> 365600 | H21: =MIN(DatiRipuliti!H1902:H2001) -> 9456648 | I21: =MIN(DatiRipuliti!I1902:I2001) -> 122400 | ... K21: =MIN(DatiRipuliti!K1902:K2001) -> 135200
A22: 1050 | B22: =MIN(DatiRipuliti!B2002:B2101) -> 550725 | C22: =MIN(DatiRipuliti!C2002:C2101) -> 4445300 | D22: =MIN(DatiRipuliti!D2002:D2101) -> 263572 | E22: =MIN(DatiRipuliti!E2002:E2101) -> 921500 | F22: =MIN(DatiRipuliti!F2002:F2101) -> 8448068 | G22: =MIN(DatiRipuliti!G2002:G2101) -> 384900 | H22: =MIN(DatiRipuliti!H2002:H2101) -> 10566990 | I22: =MIN(DatiRipuliti!I2002:I2101) -> 128600 | ... K22: =MIN(DatiRipuliti!K2002:K2101) -> 143400
A23: 1100 | B23: =MIN(DatiRipuliti!B2102:B2201) -> 604450 | C23: =MIN(DatiRipuliti!C2102:C2201) -> 4883400 | D23: =MIN(DatiRipuliti!D2102:D2201) -> 287156 | E23: =MIN(DatiRipuliti!E2102:E2201) -> 997700 | F23: =MIN(DatiRipuliti!F2102:F2201) -> 9370368 | G23: =MIN(DatiRipuliti!G2102:G2201) -> 408800 | H23: =MIN(DatiRipuliti!H2102:H2201) -> 11738585 | I23: =MIN(DatiRipuliti!I2102:I2201) -> 135800 | ... K23: =MIN(DatiRipuliti!K2102:K2201) -> 150900
A24: 1150 | B24: =MIN(DatiRipuliti!B2202:B2301) -> 660675 | C24: =MIN(DatiRipuliti!C2202:C2301) -> 5424300 | D24: =MIN(DatiRipuliti!D2202:D2301) -> 317411 | E24: =MIN(DatiRipuliti!E2202:E2301) -> 1101800 | F24: =MIN(DatiRipuliti!F2202:F2301) -> 10344905 | G24: =MIN(DatiRipuliti!G2202:G2301) -> 429800 | H24: =MIN(DatiRipuliti!H2202:H2301) -> 12963002 | I24: =MIN(DatiRipuliti!I2202:I2301) -> 139800 | ... K24: =MIN(DatiRipuliti!K2202:K2301) -> 159700
A25: 1200 | B25: =MIN(DatiRipuliti!B2302:B2401) -> 719400 | C25: =MIN(DatiRipuliti!C2302:C2401) -> 5975800 | D25: =MIN(DatiRipuliti!D2302:D2401) -> 343809 | E25: =MIN(DatiRipuliti!E2302:E2401) -> 1197900 | F25: =MIN(DatiRipuliti!F2302:F2401) -> 11371145 | G25: =MIN(DatiRipuliti!G2302:G2401) -> 450300 | H25: =MIN(DatiRipuliti!H2302:H2401) -> 14247432 | I25: =MIN(DatiRipuliti!I2302:I2401) -> 149800 | ... K25: =MIN(DatiRipuliti!K2302:K2401) -> 167000
A26: 1250 | B26: =MIN(DatiRipuliti!B2402:B2501) -> 780625 | C26: =MIN(DatiRipuliti!C2402:C2501) -> 6563100 | D26: =MIN(DatiRipuliti!D2402:D2501) -> 371171 | E26: =MIN(DatiRipuliti!E2402:E2501) -> 1280600 | F26: =MIN(DatiRipuliti!F2402:F2501) -> 12450264 | G26: =MIN(DatiRipuliti!G2402:G2501) -> 467100 | H26: =MIN(DatiRipuliti!H2402:H2501) -> 15616980 | I26: =MIN(DatiRipuliti!I2402:I2501) -> 157500 | ... K26: =MIN(DatiRipuliti!K2402:K2501) -> 175000
A27: 1300 | B27: =MIN(DatiRipuliti!B2502:B2601) -> 844350 | C27: =MIN(DatiRipuliti!C2502:C2601) -> 7234800 | D27: =MIN(DatiRipuliti!D2502:D2601) -> 401048 | E27: =MIN(DatiRipuliti!E2502:E2601) -> 1405000 | F27: =MIN(DatiRipuliti!F2502:F2601) -> 13581334 | G27: =MIN(DatiRipuliti!G2502:G2601) -> 486400 | H27: =MIN(DatiRipuliti!H2502:H2601) -> 17062751 | I27: =MIN(DatiRipuliti!I2502:I2601) -> 167300 | ... K27: =MIN(DatiRipuliti!K2502:K2601) -> 183700
A28: 1350 | B28: =MIN(DatiRipuliti!B2602:B2701) -> 910575 | C28: =MIN(DatiRipuliti!C2602:C2701) -> 7921800 | D28: =MIN(DatiRipuliti!D2602:D2701) -> 439978 | E28: =MIN(DatiRipuliti!E2602:E2701) -> 1528000 | F28: =MIN(DatiRipuliti!F2602:F2701) -> 14765009 | G28: =MIN(DatiRipuliti!G2602:G2701) -> 513300 | H28: =MIN(DatiRipuliti!H2602:H2701) -> 18570027 | I28: =MIN(DatiRipuliti!I2602:I2701) -> 174000 | ... K28: =MIN(DatiRipuliti!K2602:K2701) -> 189600
A29: 1400 | B29: =MIN(DatiRipuliti!B2702:B2801) -> 979300 | C29: =MIN(DatiRipuliti!C2702:C2801) -> 8507500 | D29: =MIN(DatiRipuliti!D2702:D2801) -> 472727 | E29: =MIN(DatiRipuliti!E2702:E2801) -> 1644000 | F29: =MIN(DatiRipuliti!F2702:F2801) -> 16002072 | G29: =MIN(DatiRipuliti!G2702:G2801) -> 534400 | H29: =MIN(DatiRipuliti!H2702:H2801) -> 20135198 | I29: =MIN(DatiRipuliti!I2702:I2801) -> 179600 | ... K29: =MIN(DatiRipuliti!K2702:K2801) -> 197800
A30: 1450 | B30: =MIN(DatiRipuliti!B2802:B2901) -> 1050525 | C30: =MIN(DatiRipuliti!C2802:C2901) -> 9228600 | D30: =MIN(DatiRipuliti!D2802:D2901) -> 505538 | E30: =MIN(DatiRipuliti!E2802:E2901) -> 1744700 | F30: =MIN(DatiRipuliti!F2802:F2901) -> 17292420 | G30: =MIN(DatiRipuliti!G2802:G2901) -> 556800 | H30: =MIN(DatiRipuliti!H2802:H2901) -> 21759591 | I30: =MIN(DatiRipuliti!I2802:I2901) -> 189300 | ... K30: =MIN(DatiRipuliti!K2802:K2901) -> 207100
A31: 1500 | B31: =MIN(DatiRipuliti!B2902:B3001) -> 1124250 | C31: =MIN(DatiRipuliti!C2902:C3001) -> 9857900 | D31: =MIN(DatiRipuliti!D2902:D3001) -> 540543 | E31: =MIN(DatiRipuliti!E2902:E3001) -> 1866700 | F31: =MIN(DatiRipuliti!F2902:F3001) -> 18636078 | G31: =MIN(DatiRipuliti!G2902:G3001) -> 574300 | H31: =MIN(DatiRipuliti!H2902:H3001) -> 23486253 | I31: =MIN(DatiRipuliti!I2902:I3001) -> 193000 | ... K31: =MIN(DatiRipuliti!K2902:K3001) -> 213700
A1048576: =SUM(A2:A1048575) -> 23250

Sheet Max
A1: n | B1: ConfrontiPessimoBS | C1: TnsPessimoBS | D1: ConfrontiPessimoIS | E1: TnsPessimoIS | F1: ConfrontiPessimoMS | G1: TnsPessimoMS | H1: ConfrontiPessimoQS | I1: TnsPessimoQS | J1: ConfrontiPessimoQSR | K1: TnsPessimoQSR
A2: 50 | B2: =MAX(DatiRipuliti!B2:B101) -> 1225 | C2: =MAX(DatiRipuliti!C2:C101) -> 728600 | D2: =MAX(DatiRipuliti!D2:D101) -> 822 | E2: =MAX(DatiRipuliti!E2:E101) -> 275300 | F2: =MAX(DatiRipuliti!F2:F101) -> 22200 | G2: =MAX(DatiRipuliti!G2:G101) -> 462800 | H2: =MAX(DatiRipuliti!H2:H101) -> 26083 | I2: =MAX(DatiRipuliti!I2:I101) -> 201200 | ... K2: =MAX(DatiRipuliti!K2:K101) -> 225800
A3: 100 | B3: =MAX(DatiRipuliti!B102:B201) -> 4950 | C3: =MAX(DatiRipuliti!C102:C201) -> 52800 | D3: =MAX(DatiRipuliti!D102:D201) -> 3000 | E3: =MAX(DatiRipuliti!E102:E201) -> 132400 | F3: =MAX(DatiRipuliti!F102:F201) -> 76305 | G3: =MAX(DatiRipuliti!G102:G201) -> 73300 | H3: =MAX(DatiRipuliti!H102:H201) -> 91469 | I3: =MAX(DatiRipuliti!I102:I201) -> 74700 | ... K3: =MAX(DatiRipuliti!K102:K201) -> 69800
A4: 150 | B4: =MAX(DatiRipuliti!B202:B301) -> 11175 | C4: =MAX(DatiRipuliti!C202:C301) -> 110300 | D4: =MAX(DatiRipuliti!D202:D301) -> 6310 | E4: =MAX(DatiRipuliti!E202:E301) -> 47600 | F4: =MAX(DatiRipuliti!F202:F301) -> 166170 | G4: =MAX(DatiRipuliti!G202:G301) -> 107800 | H4: =MAX(DatiRipuliti!H202:H301) -> 199706 | I4: =MAX(DatiRipuliti!I202:I301) -> 46700 | ... K4: =MAX(DatiRipuliti!K202:K301) -> 39300
A5: 200 | B5: =MAX(DatiRipuliti!B302:B401) -> 19900 | C5: =MAX(DatiRipuliti!C302:C401) -> 216300 | D5: =MAX(DatiRipuliti!D302:D401) -> 11203 | E5: =MAX(DatiRipuliti!E302:E401) -> 79700 | F5: =MAX(DatiRipuliti!F302:F401) -> 294277 | G5: =MAX(DatiRipuliti!G302:G401) -> 149900 | H5: =MAX(DatiRipuliti!H302:H401) -> 356749 | I5: =MAX(DatiRipuliti!I302:I401) -> 33800 | ... K5: =MAX(DatiRipuliti!K302:K401) -> 83300
A6: 250 | B6: =MAX(DatiRipuliti!B402:B501) -> 31125 | C6: =MAX(DatiRipuliti!C402:C501) -> 393100 | D6: =MAX(DatiRipuliti!D402:D501) -> 17461 | E6: =MAX(DatiRipuliti!E402:E501) -> 128100 | F6: =MAX(DatiRipuliti!F402:F501) -> 462029 | G6: =MAX(DatiRipuliti!G402:G501) -> 160300 | H6: =MAX(DatiRipuliti!H402:H501) -> 564793 | I6: =MAX(DatiRipuliti!I402:I501) -> 56600 | ... K6: =MAX(DatiRipuliti!K402:K501) -> 50200
A7: 300 | B7: =MAX(DatiRipuliti!B502:B601) -> 44850 | C7: =MAX(DatiRipuliti!C502:C601) -> 428500 | D7: =MAX(DatiRipuliti!D502:D601) -> 24642 | E7: =MAX(DatiRipuliti!E502:E601) -> 205000 | F7: =MAX(DatiRipuliti!F502:F601) -> 671818 | G7: =MAX(DatiRipuliti!G502:G601) -> 220300 | H7: =MAX(DatiRipuliti!H502:H601) -> 822349 | I7: =MAX(DatiRipuliti!I502:I601) -> 51800 | ... K7: =MAX(DatiRipuliti!K502:K601) -> 67100
A8: 350 | B8: =MAX(DatiRipuliti!B602:B701) -> 61075 | C8: =MAX(DatiRipuliti!C602:C701) -> 564800 | D8: =MAX(DatiRipuliti!D602:D701) -> 33354 | E8: =MAX(DatiRipuliti!E602:E701) -> 230800 | F8: =MAX(DatiRipuliti!F602:F701) -> 924351 | G8: =MAX(DatiRipuliti!G602:G701) -> 350700 | H8: =MAX(DatiRipuliti!H602:H701) -> 1135369 | I8: =MAX(DatiRipuliti!I602:I701) -> 63600 | ... K8: =MAX(DatiRipuliti!K602:K701) -> 82000
